Workbook

Sheet README
A1: Chaos Engineering Scenario Catalog
A2: Audience: Sr. technical leadership (program review) and the Chaos Engineering team (execution). Derived from code-based assessment artifacts, C1–C4/EAC diagrams, the recon (DTR) pipeline diagram/narrative, and prior FMEA / timeout-chain / DR work. Nothing in the catalog is invented beyond those sources; unknowns are flagged in Open Items.
A4: Sheets
A5: 1. Service Inventory | B5: The 17 Core services with archetype, DR posture, ingress, data stores, RDS Proxy status, dependencies and scheduled jobs. Source of truth for scenario targeting.
A6: 2. Scenario Catalog | B6: The full experiment catalog. One row per scenario. Filter by Wave, Fault Domain, Archetype, Target Service or Injection Plane.
A7: 3. Priority Model | B7: Scoring definitions for Likelihood and Severity, and how Priority and Wave assignment work.
A8: 4. Wave Plan | B8: Execution waves with theme, entry/exit criteria and live scenario counts.
A9: 5. Coverage Matrix | B9: Fault Domain × Wave and Fault Domain × Injection Plane counts, computed live from the catalog.
A10: 6. Open Items | B10: Unknowns, confirmations pending, and documentation gaps that gate specific scenarios.
A11: 7. App Scan Instructions | B11: Durable method for scanning any application repo (Maven multi-module) for resilience-relevant facts: dependency/version census, resilience config, timeout chain, retry amplification inputs, Kafka consumer config, idempotency evidence, anti-pattern sweep, and perf-vs-prod profile diff. Re-runnable on future services unchanged.
A12: 8. Infra Scan Instructions | B12: Durable method for discovering cloud components from infrastructure-as-code (tool-agnostic: Terraform/CDK/CloudFormation/Serverless), reconciling them against the Service Inventory tab, and onboarding new AWS components/services into the taxonomy going forward.
A14: Key concepts
A15: Injection plane | B15: Infrastructure = fault injected below the app (FIS, network, AWS resources). Application = fault injected inside the request path (latency/exceptions/errors via app-level tooling or a proxy). Compound = multiple simultaneous faults. Detection = the hypothesis is about observability, not recovery.
A16: Dual success criteria | B16: Every scenario has TWO pass conditions: the system behaved as hypothesized AND the fault was detected/alerted correctly (Dynatrace + CloudWatch). A fault that recovers silently is a FAILED experiment. Detection baseline scenarios (CE-OBS-*) run in Wave 1 for this reason.
A17: PERF validity | B17: High = result transfers to PROD with confidence. Medium = transfers with caveats (capacity/data-volume/config deltas). Low = PERF result is indicative only; needs eventual PROD validation or explicit delta analysis.
A18: Steady state first | B18: A scenario is not runnable until its steady-state signal exists and is trusted. If the SLI/dashboard for the hypothesis is missing or unvalidated, that is itself a Wave-1 finding.
A20: How to use (chaos team)
A21: Cells to fill in | B21: YELLOW cells are yours to populate: FMEA Ref (map each scenario to the existing FMEA scenario IDs — ASSESSED items first), Journeys (which of the 16 official journeys the scenario exercises), and Status as work progresses (Proposed → Ready → Executed → Confirmed / Finding).
A22: Example of a filled row | B22: CE-COM-01 carries example values in its FMEA Ref and Journeys cells (marked 'EXAMPLE —') showing the expected format. Replace with real IDs.
A23: Prerequisites | B23: Prereq IDs = scenarios that must be Confirmed before this one is meaningful (singles before compounds). Waves are sequenced so prerequisites always land in an earlier or same wave.
A24: Governance | B24: Wave 1–2 run in PERF game days with evidence capture per run. Wave 3–4 include coordination-heavy and DR drills; treat each as a scheduled event with stakeholder sign-off. Production experimentation is out of scope for this catalog version.

Sheet Service Inventory
A1: # | B1: Service | C1: Acronym | D1: APG | E1: Archetype | F1: DR Posture | G1: Ingress | H1: Data Stores | I1: RDS Proxy | J1: Core-internal Sync Deps | K1: External Sync Deps | L1: Async Produces / Consumes | M1: Scheduled Jobs | N1: Doc Status / Notes
A2: 1 | B2: Account Locator Component | C2: ALS | D2: LOCR | E2: Sync API + batch extract — mixed | F2: Active/Active (latency routing) | G2: R53→NLB→API GW→NLB→ALB→ECS | H2: Aurora (direct), ElastiCache, S3 (RDS→S3 Lambda) | I2: No (direct) | J2: ACL (Register) | K2: Inbound only (ARR/FAP/DCPA/DCP/Payments/SPG/OCS) | L2: Prod: Locator Event→MBUS→Datalake; Batch: Lambda→S3→MFT→EDX | M2: Batch extract | N2: OK
A3: 2 | B3: Account Reference Management | C3: ARM | D3: ACCT | E3: Sync API | F3: Active/Active | G3: R53→NLB→API GW→NLB→ALB→ECS | H3: Aurora (direct), ElastiCache | I3: No (direct) | J3: Inbound only (SAM/AFM/DBE/DTE/DSM/DCM) | K3: none | L3: none shown | M3: none | N3: OK
A4: 3 | B4: Core Account Management | C4: SAM | D4: ACCT | E4: Orchestrator (acct lifecycle) — mixed | F4: Active/Passive | G4: R53→NLB→API GW→NLB→ALB→ECS (from SMB/ARR) | H4: Aurora (direct — Core DB) | I4: No (direct) | J4: ALS, ARM, AFM, ACL | K4: CBS (Account Mgmt) | L4: Prod: Core Acct Change→MBUS→Datalake; Cons: MBUS incl. RECN EOD Completion | M4: none | N4: OK
A5: 4 | B5: Account Feature Management | C5: AFM | D5: ACCT | E5: Sync API + event publisher — mixed | F5: Active/Passive | G5: R53→NLB→API GW→NLB→ALB→ECS (from SAM) | H5: Aurora (direct — AFM DB), ElastiCache | I5: No (direct) | J5: MCC, DBE, DSM, DCM, ARM, ACL | K5: CBS Posting, CBS Transaction | L5: Prod: Feature State Change→MBUS (→DCP-TA, Datalake) | M5: none | N5: OK
A6: 5 | B6: Account Locator Admin Tool | C6: DLAT | D6: LOCR | E6: Not shown (infra diagram only) | F6: Active/Passive (per rule) | G6: R53→NLB→ALB→ECS — NO API GW | H6: Aurora (direct), S3 | I6: No (direct) | J6: not shown | K6: not shown | L6: not shown | M6: none | N6: GAP — dependencies undocumented
A7: 6 | B7: Attribute Change Log | C7: ACL | D7: ACCT | E7: Event aggregator/consumer + Sync API — mixed | F7: Active/Passive (per rule) | G7: R53→NLB→API GW→NLB→ALB→ECS | H7: Aurora (direct — History Datastore) | I7: No (direct) | J7: Receives SAM/AFM/ALS registrations | K7: none | L7: Cons: Core Acct Change, Feature Change (SAM/AFM/ALS) | M7: none | N7: OK
A8: 7 | B8: Core Subledger Management | C8: DSM | D8: REFD | E8: Sync API + event publisher — mixed | F8: Active/Passive; cross-region repl., bidirectional Aurora | G8: External NLB→API GW→Internal NLB→ALB→ECS Anywhere | H8: Aurora (direct — writer/reader nodes), IN-MEMORY HASHMAP | I8: No (direct) | J8: MCC, ARM (migration lookup) | K8: CBS (Subledger+RoutingRule, Balance Inquiry), Payments/MMS | L8: Prod: Subledger CUD→MBUS→AU+Continuum/DataLake; +Migration Topic | M8: none | N8: In-memory state — see CE-COM-05
A9: 8 | B9: Spend-Track Experience Svc | C9: SSE | D9: REFD | E9: No diagram provided | F9: 3-Active (+us-west-2, stateless per rule) | G9: no diagram | H9: no diagram | I9: TBC | J9: no diagram | K9: no diagram | L9: no diagram | M9: none | N9: GAP — no artifact at all; scenarios blocked
A10: 9 | B10: Tasks Experience Svc | C10: CHE | D10: ENRC | E10: Edge/BFF | F10: 3-Active (+us-west-2, stateless) | G10: Via DPS Proxy/Digital; shares 900069 ingress | H10: none of its own shown | I10: n/a | J10: DCM (Task Inquiry for Nudges), MCC (Spend Categories) | K10: none shown | L10: none shown | M10: none | N10: Reconstructed from other diagrams
A11: 10 | B11: Transaction Experience Svc | C11: TE | D11: ALRT | E11: Edge/BFF | F11: 3-Active (+us-west-2) | G11: Akamai→CTC→DPS Proxy→Transit GW→R53→API GW (AuthAnywhere token validate)→NLB→ALB→ECS | H11: none (stateless) | I11: n/a | J11: none | K11: ChannelContext, ETU/TU Transactions, GKP on-prem via Envoy, AuthAnywhere | L11: none shown | M11: none | N11: OK
A12: 11 | B12: MCC Data Management Svc | C12: MCC | D12: REFD | E12: Sync API (ref data) + scheduled pipeline — mixed | F12: Active/Passive; DR: PILOT LIGHT | G12: API GW→NLB→ALB→ECS (+ On-Prem API GW); EventBridge scheduler (ETU pull) | H12: Aurora (direct — Local Data Store), S3 (config) | I12: No (direct) | J12: Inbound only (DSM, SAM/Acct Creation, Tasks Exp) | K12: ETU (GET Reference Data, scheduled) | L12: Scheduler-triggered ETU pull; writes config→S3; no Kafka publish | M12: EventBridge ETU pull | N12: OK
A13: 12 | B13: Core Task Management | C13: DCM | D13: ENRC | E13: Sync API (CRUD) + event publisher + scheduled job — mixed | F13: Active/Passive (Warm Standby) | G13: Via DPS Proxy/Digital & Banking Payments→NLB→NLB→ALB (+API GW Regional Endpt); weekly-job scheduler via SQS | H13: Aurora (RDS PROXY, separate Global cluster), ElastiCache (shared), SQS+DLQ | I13: YES | J13: ARM, SAM, Core Alerts (DCC 900070) | K13: CBS (posting/balance inquiry via Digital Payments) | L13: Prod: Task Life Cycle→MBUS (→Alerts, DTE); SQS: weekly future-task job | M13: Weekly SQS-driven job | N13: OK
... A18: 17 | B18: Core Alerts | C18: DAL | D18: ALRT | E18: Event processor + API intake — mixed | F18: Active/Passive | G18: Kafka (Enriched Txn CUD, Task Lifecycle, D2 Alert Topic) + API; CRON scheduler (failure recovery); API GW/NLB/ALB/R53 | H18: Aurora (direct — Alerts DB / RDS Global) | I18: No (direct) | J18: none | K18: CSU (Fetch Parent/Child, payload enrichment) | L18: Cons: Enriched Txn CUD + Task Lifecycle. Prod: enriched alerts→Notify Alert Topic→NOTIFY | M18: Cron (failure recovery) | N18: OK

Sheet Scenario Catalog
A1: ID | B1: Scenario | C1: Fault Domain | D1: Injection Plane | E1: Archetype(s) | F1: Target Service(s) | G1: Fault / Injection | H1: Hypothesis (steady state holds if…) | I1: Tooling / Method | J1: Blast Radius | K1: Abort Condition | L1: Success — System | M1: Success — Detection | N1: PERF Validity | O1: PERF Note | P1: Likelihood (1-5) | Q1: Severity (1-5) | R1: Priority | S1: Wave | T1: Prereq IDs | U1: FMEA Ref (FILL) | V1: Journeys (FILL) | W1: Status | X1: Likelihood Tier | Y1: Risk Rating
A2: CE-COM-01 | B2: Single Fargate task termination — sync API | C2: Compute | D2: Infrastructure | E2: Sync API | F2: SAM (repeat per sync API) | G2: Terminate 1 running task of the service under steady synthetic load. | H2: ECS replaces the task; ALB deregisters/drains; journey SLI stays within SLO; zero 5xx beyond in-flight requests. | I2: FIS aws:ecs:stop-task | J2: Single task | K2: SLI breach > 2 min | L2: Task replaced ≤ target time; no request loss beyond in-flight; connection re-establishment clean. | M2: Dynatrace detects task churn; no false-positive paging for single-task events (noise calibration). | N2: High | O2: Recovery mechanics transfer; scaled-down task counts change % impact only. | P2: 4 | Q2: 2 | R2: =P2*Q2 | S2: 1 | U2: EXAMPLE — FMEA-ECS-004, FMEA-ECS-011 | V2: EXAMPLE — J03, J07 | W2: Proposed | X2: =IF(P2=5,"Almost Certain",IF(P2=4,"Likely",IF(P2=3,"Possible",IF(P2=2,"Unlikely","Rare")))) | Y2: =IF(R2>=16,"Critical",IF(R2>=9,"High",IF(R2>=4,"Medium","Opportunistic")))
A3: CE-COM-02 | B3: Bulk task termination (50%) under load | C3: Compute | D3: Infrastructure | E3: Sync API | F3: ARM, SAM | G3: Terminate 50% of tasks simultaneously under load. | H3: Remaining tasks absorb load without pool/thread exhaustion; scale-out restores capacity; SLI degrades within tolerated bounds. | I3: FIS aws:ecs:stop-task (percentage) | J3: One service | K3: Error rate >5% for >3 min | L3: No cascading failure to callers; scale-out completes; queuing recovers. | M3: Capacity alarm fires; Dynatrace shows saturation before errors. | N3: Medium | O3: PERF task counts/scaling policies differ from PROD — % result indicative only. | P3: 3 | Q3: 3 | R3: =P3*Q3 | S3: 1 | T3: CE-COM-01 | W3: Proposed | X3: =IF(P3=5,"Almost Certain",IF(P3=4,"Likely",IF(P3=3,"Possible",IF(P3=2,"Unlikely","Rare")))) | Y3: =IF(R3>=16,"Critical",IF(R3>=9,"High",IF(R3>=4,"Medium","Opportunistic")))
A4: CE-COM-03 | B4: Task kill during rolling deployment | C4: Compute | D4: Infrastructure | E4: Sync API | F4: One sync API | G4: Inject task termination while a deployment is replacing tasks. | H4: Deployment circuit breaker / min-healthy settings prevent capacity dropping below safe floor; rollback triggers if needed. | I4: FIS + pipeline coordination | J4: One service | K4: Healthy count < min for >2 min | L4: No dual-capacity loss; deploy completes or rolls back cleanly. | M4: Deploy-time alerting distinguishes deployment churn from failure. | N4: High | O4: Deployment config parity assumed — verify. | P4: 3 | Q4: 3 | R4: =P4*Q4 | S4: 2 | T4: CE-COM-01 | W4: Proposed | X4: =IF(P4=5,"Almost Certain",IF(P4=4,"Likely",IF(P4=3,"Possible",IF(P4=2,"Unlikely","Rare")))) | Y4: =IF(R4>=16,"Critical",IF(R4>=9,"High",IF(R4>=4,"Medium","Opportunistic")))
A5: CE-COM-04 | B5: Event-processor task kill mid-consumption | C5: Compute | D5: Infrastructure | E5: Event processor | F5: DBE, DTE | G5: Kill a consumer task while it processes a batch of CBS events. | H5: Offsets uncommitted messages are redelivered; enrichment is idempotent — no lost and no duplicate enriched events downstream (AU/ETU). | I5: FIS aws:ecs:stop-task | J5: One consumer group member | K5: Consumer lag > threshold, no drain | L5: Rebalance completes; redelivered messages produce identical enriched output exactly once (effective). | M5: Lag + rebalance visible in Dynatrace; DLQ/poison alarms silent. | N5: High | O5: Idempotency logic is environment-independent. | P5: 4 | Q5: 4 | R5: =P5*Q5 | S5: 1 | W5: Proposed | X5: =IF(P5=5,"Almost Certain",IF(P5=4,"Likely",IF(P5=3,"Possible",IF(P5=2,"Unlikely","Rare")))) | Y5: =IF(R5>=16,"Critical",IF(R5>=9,"High",IF(R5>=4,"Medium","Opportunistic")))
A6: CE-COM-05 | B6: DSM task recycle — in-memory hashmap loss | C6: Compute | D6: Infrastructure | E6: Sync API (stateful) | F6: DSM (+DSC warmer) | G6: Recycle DSM tasks; measure window where in-memory subledger map is cold before DSC/ElastiCache warm state is usable. | H6: DSM serves correct responses during warm-up (falls back to Aurora/ElastiCache) with bounded latency penalty; no wrong answers from empty map. | I6: FIS aws:ecs:stop-task | J6: DSM only | K6: Incorrect subledger responses | L6: Zero correctness violations; warm-up window quantified; fallback path exercised. | M6: Warm-up window observable as metric; DSC warmer health alarmed. | N6: High | O6: Pattern risk is design-level, not capacity-level. | P6: 4 | Q6: 4 | R6: =P6*Q6 | S6: 1 | W6: Proposed | X6: =IF(P6=5,"Almost Certain",IF(P6=4,"Likely",IF(P6=3,"Possible",IF(P6=2,"Unlikely","Rare")))) | Y6: =IF(R6>=16,"Critical",IF(R6>=9,"High",IF(R6>=4,"Medium","Opportunistic")))
A7: CE-COM-06 | B7: ECR image pull failure during scale-out | C7: Compute | D7: Infrastructure | E7: Any | F7: One sync API | G7: Block image pulls (registry deny / endpoint block in PERF) then force scale-out. | H7: Existing tasks keep serving; scale-out failure is alarmed; no flapping replacement loop kills healthy capacity. | I7: Custom (endpoint/registry policy) | J7: One service | K7: Healthy capacity shrinking | L7: Steady state maintained on existing tasks; clear failure signal. | M7: Scale-out failure alarm exists and fires (suspected gap). | N7: High | O7: — | P7: 2 | Q7: 3 | R7: =P7*Q7 | S7: 2 | W7: Proposed | X7: =IF(P7=5,"Almost Certain",IF(P7=4,"Likely",IF(P7=3,"Possible",IF(P7=2,"Unlikely","Rare")))) | Y7: =IF(R7>=16,"Critical",IF(R7>=9,"High",IF(R7>=4,"Medium","Opportunistic")))
A8: CE-COM-07 | B8: Memory pressure → container OOM behavior | C8: Resource | D8: Application | E8: Sync API | F8: One JVM service | G8: Drive heap growth via app-level memory assault until container limit. | H8: OOM kill is clean (task replaced) rather than gray degradation; no long GC-driven brownout serving errors. | I8: App-level (Chaos Monkey for Spring Boot / stress endpoint) | J8: One task | K8: SLI breach | L8: Fail-fast behavior; replacement clean; heap/GC limits tuned. | M8: GC/heap alerting catches degradation BEFORE OOM. | N8: High | O8: JVM behavior transfers. | P8: 3 | Q8: 3 | R8: =P8*Q8 | S8: 2 | T8: CE-COM-01 | W8: Proposed | X8: =IF(P8=5,"Almost Certain",IF(P8=4,"Likely",IF(P8=3,"Possible",IF(P8=2,"Unlikely","Rare")))) | Y8: =IF(R8>=16,"Critical",IF(R8>=9,"High",IF(R8>=4,"Medium","Opportunistic")))
A9: CE-COM-08 | B9: Scheduled-job duplicate / missed execution | C9: Compute | D9: Application | E9: Scheduled job | F9: DCM weekly job, MCC ETU pull, DAL cron | G9: Run service at >1 task through a scheduled window; separately kill task at trigger time. | H9: Job fires exactly once per window (locking/leader election proven); a missed window is detected and recovered per design. | I9: Scale/kill + job observation | J9: Job outputs | K9: Duplicate side-effects detected | L9: No duplicate task-job effects / double ETU pull / double alert recovery; missed-window path defined. | M9: Missed or duplicate execution alarms (suspected gap for all three). | N9: High | O9: Logic-level, environment-independent. | P9: 3 | Q9: 4 | R9: =P9*Q9 | S9: 1 | W9: Proposed | X9: =IF(P9=5,"Almost Certain",IF(P9=4,"Likely",IF(P9=3,"Possible",IF(P9=2,"Unlikely","Rare")))) | Y9: =IF(R9>=16,"Critical",IF(R9>=9,"High",IF(R9>=4,"Medium","Opportunistic")))
A10: CE-DB-01 | B10: Aurora writer failover — RDS-Proxy-fronted | C10: Data-Aurora | D10: Infrastructure | E10: Mixed (ENRC) | F10: DCM, DBE, DTE | G10: Trigger in-region writer failover on the proxy-fronted cluster under load. | H10: RDS Proxy preserves/pins client connections; app-visible impact limited to brief write latency; no connection storm. | I10: FIS aws:rds / failover-db-cluster | J10: ENRC cluster | K10: Error rate >5% / 3 min | L10: Failover ≤ target; HikariCP pools stable; writes resume without app restarts. | M10: DB failover event alarmed; Dynatrace DB-layer signal correct. | N10: Medium | O10: Instance class + data volume affect failover duration. | P10: 3 | Q10: 4 | R10: =P10*Q10 | S10: 1 | W10: Proposed | X10: =IF(P10=5,"Almost Certain",IF(P10=4,"Likely",IF(P10=3,"Possible",IF(P10=2,"Unlikely","Rare")))) | Y10: =IF(R10>=16,"Critical",IF(R10>=9,"High",IF(R10>=4,"Medium","Opportunistic")))
A11: CE-DB-02 | B11: Aurora writer failover — direct-connection | C11: Data-Aurora | D11: Infrastructure | E11: Sync API | F11: SAM (Core DB) | G11: Same failover on a direct (non-proxy) cluster under load. | H11: aws-jdbc-wrapper fast-failover redirects connections within pool timeout budget; documented behavior matches FMEA ledger. | I11: FIS / failover-db-cluster | J11: Core DB cluster | K11: Error rate >5% / 3 min | L11: Recovery time quantified; asymmetry vs CE-DB-01 documented as evidence for proxy adoption decision. | M11: Same detection as DB-01. | N11: Medium | O11: Same caveats as DB-01. | P11: 3 | Q11: 4 | R11: =P11*Q11 | S11: 1 | T11: CE-DB-01 | W11: Proposed | X11: =IF(P11=5,"Almost Certain",IF(P11=4,"Likely",IF(P11=3,"Possible",IF(P11=2,"Unlikely","Rare")))) | Y11: =IF(R11>=16,"Critical",IF(R11>=9,"High",IF(R11>=4,"Medium","Opportunistic")))
A12: CE-DB-03 | B12: Connection storm on writer promotion | C12: Data-Aurora | D12: Compound | E12: Sync API | F12: SAM + heaviest callers | G12: Writer failover while pools are near max and load is high — deliberate worst case. | H12: HikariCP settings (max pool, connection timeout, validation) prevent thundering-herd reconnect storm from delaying promotion recovery. | I12: FIS + load profile | J12: Core DB + callers | K12: DB CPU pegged >5 min | L12: Reconnect ramp controlled; total brownout window within FMEA-assessed bound. | M12: Pool saturation metrics visible pre-failure. | N12: Low | O12: Pool sizes & instance class differ in PERF — directional only; flag for PROD-parity retest. | P12: 2 | Q12: 5 | R12: =P12*Q12 | S12: 3 | T12: CE-DB-02,CE-APP-05 | W12: Proposed | X12: =IF(P12=5,"Almost Certain",IF(P12=4,"Likely",IF(P12=3,"Possible",IF(P12=2,"Unlikely","Rare")))) | Y12: =IF(R12>=16,"Critical",IF(R12>=9,"High",IF(R12>=4,"Medium","Opportunistic")))
A13: CE-DB-04 | B13: Reader node failure (reader/writer split) | C13: Data-Aurora | D13: Infrastructure | E13: Sync API | F13: Proxy-fronted ENRC services | G13: Kill/reboot a reader instance under read-heavy load. | H13: Reads redistribute to surviving readers/writer without error spike; reader endpoint DNS behavior within TTL budget. | I13: FIS aws:rds:reboot-db-instances | J13: One reader | K13: Read errors sustained | L13: Read continuity; latency bump bounded. | M13: Reader loss alarmed distinctly from writer events. | N13: High | O13: — | P13: 3 | Q13: 3 | R13: =P13*Q13 | S13: 2 | T13: CE-DB-01 | W13: Proposed | X13: =IF(P13=5,"Almost Certain",IF(P13=4,"Likely",IF(P13=3,"Possible",IF(P13=2,"Unlikely","Rare")))) | Y13: =IF(R13>=16,"Critical",IF(R13>=9,"High",IF(R13>=4,"Medium","Opportunistic")))
A14: CE-DB-05 | B14: Global replication lag / stale-read tolerance | C14: Data-Aurora | D14: Infrastructure | E14: All Aurora users | F14: Global clusters | G14: Induce/observe elevated cross-region replication lag (heavy write load; direct lag injection has no FIS action — method gap). | H14: Services and DR runbooks tolerate documented lag; RPO assumptions (incl. DBE 'RPO PoF') hold under stress. | I14: Custom (write-load driven) | J14: Secondary region reads | K14: Lag beyond RPO assumption | L14: Measured lag vs documented RPO; consumers of secondary data behave. | M14: Replication-lag alarm exists with correct threshold. | N14: Low | O14: Data volume in PERF understates PROD lag — treat as method validation. | P14: 2 | Q14: 4 | R14: =P14*Q14 | S14: 3 | W14: Proposed | X14: =IF(P14=5,"Almost Certain",IF(P14=4,"Likely",IF(P14=3,"Possible",IF(P14=2,"Unlikely","Rare")))) | Y14: =IF(R14>=16,"Critical",IF(R14>=9,"High",IF(R14>=4,"Medium","Opportunistic")))
A15: CE-DB-06 | B15: Managed planned global failover | C15: Data-Aurora | D15: Infrastructure | E15: All | F15: Aurora Global (per cluster) | G15: Execute managed planned failover us-east-1→us-east-2. | H15: Failover completes within documented window; applications reconnect to new writer; replication reverses cleanly. | I15: AWS managed operation | J15: One global cluster | K15: Failback risk identified | L15: End-to-end timing evidence per cluster; app reconnect behavior per proxy/direct split. | M15: Region-level DB alarms coherent during transition. | N15: Medium | O15: Cluster sizing deltas. | P15: 2 | Q15: 4 | R15: =P15*Q15 | S15: 3 | T15: CE-DB-01,CE-DB-02 | W15: Proposed | X15: =IF(P15=5,"Almost Certain",IF(P15=4,"Likely",IF(P15=3,"Possible",IF(P15=2,"Unlikely","Rare")))) | Y15: =IF(R15>=16,"Critical",IF(R15>=9,"High",IF(R15>=4,"Medium","Opportunistic")))
A16: CE-DB-07 | B16: Unplanned global failover (detach & promote) | C16: Data-Aurora | D16: Infrastructure | E16: All | F16: Aurora Global (per cluster) | G16: Simulate region loss: detach secondary and promote (drill). | H16: Promotion + app cutover meets RTO; data loss within RPO; procedure executable by on-call from runbook alone. | I16: Drill (manual/scripted) | J16: One global cluster + dependents | K16: Any ambiguity in runbook | L16: RTO/RPO evidence; stale-writer protection confirmed (see DB-08). | M16: All failover alarms/dashboards correct in surviving region. | N16: Low | O16: PERF topology parity required; data volume affects timing. | P16: 1 | Q16: 5 | R16: =P16*Q16 | S16: 4 | T16: CE-DB-06 | W16: Proposed | X16: =IF(P16=5,"Almost Certain",IF(P16=4,"Likely",IF(P16=3,"Possible",IF(P16=2,"Unlikely","Rare")))) | Y16: =IF(R16>=16,"Critical",IF(R16>=9,"High",IF(R16>=4,"Medium","Opportunistic")))
A17: CE-DB-08 | B17: Stale writer endpoint after promotion | C17: Data-Aurora | D17: Application | E17: All Aurora users | F17: Sample per driver config | G17: After promotion, verify no service continues writing to old-region endpoint (driver DNS caching, wrapper topology refresh). | H17: aws-jdbc-wrapper topology awareness prevents split-brain writes; any cached-endpoint writes fail closed. | I17: Post-drill verification + custom probe | J17: Data integrity | K17: Any write accepted by old writer | L17: Zero writes to demoted writer; wrapper refresh timing quantified. | M17: Cross-region write-attempt visibility exists (likely gap). | N17: High | O17: Driver behavior transfers. | P17: 2 | Q17: 5 | R17: =P17*Q17 | S17: 3 | T17: CE-DB-06 | W17: Proposed | X17: =IF(P17=5,"Almost Certain",IF(P17=4,"Likely",IF(P17=3,"Possible",IF(P17=2,"Unlikely","Rare")))) | Y17: =IF(R17>=16,"Critical",IF(R17>=9,"High",IF(R17>=4,"Medium","Opportunistic")))
A18: CE-DB-09 | B18: IAM auth token failure (aws-jdbc-wrapper) | C18: Data-Aurora | D18: Infrastructure | E18: All (no static DB passwords) | F18: One sync API | G18: Deny IAM DB-auth token generation (perf-scoped IAM policy) for the service role. | H18: Existing connections continue (token is connect-time only); NEW connections fail with clear error; pool contraction is alarmed before exhaustion. | I18: Custom (IAM deny in PERF) | J18: One service's new connections | K18: Full pool exhaustion | L18: Degradation curve understood; recovery instant on policy restore. | M18: Auth-failure signature distinct in logs/alerts vs generic DB errors. | N18: High | O18: IAM mechanics identical across envs. | P18: 2 | Q18: 4 | R18: =P18*Q18 | S18: 2 | W18: Proposed | X18: =IF(P18=5,"Almost Certain",IF(P18=4,"Likely",IF(P18=3,"Possible",IF(P18=2,"Unlikely","Rare")))) | Y18: =IF(R18>=16,"Critical",IF(R18>=9,"High",IF(R18>=4,"Medium","Opportunistic")))
A19: CE-DB-10 | B19: RDS Proxy endpoint unavailability | C19: Data-Aurora | D19: Infrastructure | E19: Mixed (ENRC) | F19: DCM, DBE, DTE | G19: Block proxy endpoint (SG/NACL in PERF) — the proxy as its own failure point. | H19: Services fail fast per timeout chain (no hang); recovery on restore without restart; proxy-as-SPOF risk quantified for the 3 ENRC services. | I19: Custom (network deny) | J19: ENRC DB access | K19: Hang > timeout budget | L19: Timeout chain honors documented order; no thread pile-up. | M19: Proxy health distinct from cluster health in monitoring. | N19: High | O19: — | P19: 2 | Q19: 4 | R19: =P19*Q19 | S19: 2 | T19: CE-EDGE-01 | W19: Proposed | X19: =IF(P19=5,"Almost Certain",IF(P19=4,"Likely",IF(P19=3,"Possible",IF(P19=2,"Unlikely","Rare")))) | Y19: =IF(R19>=16,"Critical",IF(R19>=9,"High",IF(R19>=4,"Medium","Opportunistic")))
A20: CE-CACHE-01 | B20: ElastiCache primary failover | C20: Cache | D20: Infrastructure | E20: Sync API / Event processor | F20: Shared cluster users (ARM, AFM, DBE, DTE, DCM) | G20: Fail over primary→replica on the shared Redis cluster. | H20: Clients reconnect within seconds; brief error/latency blip absorbed by callers; no data-correctness impact. | I20: FIS aws:elasticache / console failover | J20: Shared cache | K20: Errors sustained >2 min | L20: Reconnect clean; SLI blip bounded. | M20: Cache failover event alarmed. | N20: High | O20: — | P20: 3 | Q20: 3 | R20: =P20*Q20 | S20: 1 | W20: Proposed | X20: =IF(P20=5,"Almost Certain",IF(P20=4,"Likely",IF(P20=3,"Possible",IF(P20=2,"Unlikely","Rare")))) | Y20: =IF(R20>=16,"Critical",IF(R20>=9,"High",IF(R20>=4,"Medium","Opportunistic")))
A21: CE-CACHE-02 | B21: Full cache cluster unavailable | C21: Cache | D21: Infrastructure | E21: Sync API | F21: ARM, AFM (cache-dependent APIs) | G21: Block all access to Redis for the service under load. | H21: Services degrade to Aurora-backed path (or defined degraded mode) — slower but correct; Aurora absorbs amplified read load. | I21: Custom (SG deny) | J21: Cache-dependent services | K21: Aurora saturation | L21: Correctness preserved; amplification factor measured (input to CE-CMP-05). | M21: Cache-down + DB-amplification both visible. | N21: Medium | O21: Aurora headroom differs in PERF — amplification ratio transfers, absolute capacity doesn't. | P21: 2 | Q21: 4 | R21: =P21*Q21 | S21: 2 | T21: CE-CACHE-01 | W21: Proposed | X21: =IF(P21=5,"Almost Certain",IF(P21=4,"Likely",IF(P21=3,"Possible",IF(P21=2,"Unlikely","Rare")))) | Y21: =IF(R21>=16,"Critical",IF(R21>=9,"High",IF(R21>=4,"Medium","Opportunistic")))
A22: CE-CACHE-03 | B22: Cache auth token retrieval failure (VaultSM ASM) | C22: Cache | D22: Infrastructure | E22: All cache users | F22: One service | G22: Deny ASM secret retrieval for Redis auth token; include a task recycle during the outage. | H22: Running tasks unaffected (token held); RECYCLED tasks fail startup loudly, not silently degraded; no crash-loop masking. | I22: Custom (ASM deny in PERF) | J22: One service | K22: Silent degraded serving | L22: Startup-dependency risk quantified; crash-loop backoff sane. | M22: Secret-retrieval failure alarmed distinctly. | N22: High | O22: — | P22: 2 | Q22: 4 | R22: =P22*Q22 | S22: 2 | W22: Proposed | X22: =IF(P22=5,"Almost Certain",IF(P22=4,"Likely",IF(P22=3,"Possible",IF(P22=2,"Unlikely","Rare")))) | Y22: =IF(R22>=16,"Critical",IF(R22>=9,"High",IF(R22>=4,"Medium","Opportunistic")))
A23: CE-CACHE-04 | B23: Cold-cache stampede | C23: Cache | D23: Infrastructure | E23: Sync API | F23: ARM/AFM + Aurora | G23: Flush cache under load; measure stampede onto Aurora. | H23: Request coalescing / TTL jitter / warmer limits stampede; Aurora load stays under safe threshold. | I23: Custom (FLUSH in PERF) | J23: Cache + backing DB | K23: Aurora saturation | L23: Stampede controls proven or gap documented. | M23: Amplification visible as leading indicator. | N23: Medium | O23: Absolute DB capacity differs. | P23: 3 | Q23: 4 | R23: =P23*Q23 | S23: 2 | T23: CE-CACHE-02 | W23: Proposed | X23: =IF(P23=5,"Almost Certain",IF(P23=4,"Likely",IF(P23=3,"Possible",IF(P23=2,"Unlikely","Rare")))) | Y23: =IF(R23>=16,"Critical",IF(R23>=9,"High",IF(R23>=4,"Medium","Opportunistic")))
A24: CE-CACHE-05 | B24: ElastiCache loss MID-RECON (EOD datastore) | C24: Cache | D24: Infrastructure | E24: Recon/pipeline | F24: DTR | G24: Fail Redis while DTR is mid-reconciliation (EOD txn cache in use). | H24: Recon detects datastore loss, fails safe (no partial/incorrect postings), and is restartable — re-pull from CBS EOD API rather than corrupt continuation. | I24: FIS/console failover + custom timing | J24: Recon run | K24: ANY posting correction from bad state | L24: No incorrect Posting-API corrections; rerun completes in window; Redis-as-datastore (not cache) risk documented. | M24: Mid-run datastore loss pages recon on-call immediately. | N24: High | O24: Logic-level; file volumes smaller in PERF (timing caveat). | P24: 2 | Q24: 5 | R24: =P24*Q24 | S24: 2 | T24: CE-CACHE-01,CE-PIPE-10 | W24: Proposed | X24: =IF(P24=5,"Almost Certain",IF(P24=4,"Likely",IF(P24=3,"Possible",IF(P24=2,"Unlikely","Rare")))) | Y24: =IF(R24>=16,"Critical",IF(R24>=9,"High",IF(R24>=4,"Medium","Opportunistic")))
A25: CE-CACHE-06 | B25: Recon purge failure — memory accumulation | C25: Cache | D25: Detection | E25: Recon/pipeline | F25: DTR | G25: Suppress the post-recon purge (step 10) across simulated cycles. | H25: Memory-pressure trend is detected well before eviction threatens the next recon's EOD dataset. | I25: Custom (skip purge in PERF) | J25: Redis capacity trend | K25: n/a (observation) | L25: Days-to-failure runway quantified. | M25: Trend alarm exists with adequate lead time (suspected gap). | N25: High | O25: Trend math transfers. | P25: 2 | Q25: 4 | R25: =P25*Q25 | S25: 2 | W25: Proposed | X25: =IF(P25=5,"Almost Certain",IF(P25=4,"Likely",IF(P25=3,"Possible",IF(P25=2,"Unlikely","Rare")))) | Y25: =IF(R25>=16,"Critical",IF(R25>=9,"High",IF(R25>=4,"Medium","Opportunistic")))
A26: CE-CACHE-07 | B26: Post-regional-failover cold cache | C26: Cache | D26: Infrastructure | E26: All cache users | F26: Surviving-region Redis | G26: Per-region static clusters ⇒ regional failover lands on a cold cache. Simulate by directing load at standby-region cache. | H26: Surviving region absorbs cold-start read amplification during DR without breaching Aurora capacity. | I26: Custom + load | J26: Standby region | K26: Aurora saturation | L26: Cold-start curve measured; feeds DR capacity plan and CE-CMP-05. | M26: Standby-region dashboards actually populated (validate). | N26: Medium | O26: Standby capacity parity TBD. | P26: 3 | Q26: 4 | R26: =P26*Q26 | S26: 3 | T26: CE-CACHE-04 | W26: Proposed | X26: =IF(P26=5,"Almost Certain",IF(P26=4,"Likely",IF(P26=3,"Possible",IF(P26=2,"Unlikely","Rare")))) | Y26: =IF(R26>=16,"Critical",IF(R26>=9,"High",IF(R26>=4,"Medium","Opportunistic")))
A27: CE-KFK-01 | B27: MBUS cluster unreachable | C27: Messaging-Kafka | D27: Infrastructure | E27: Event processor + publishers | F27: DBE, DTE, DSC, DAL, DSM, SAM, DCM, AFM | G27: Blackhole network path to on-prem MBUS (C001/C002). | H27: Consumers idle without crash-loop; producers buffer/queue per config without data loss or unbounded memory; full catch-up on restore with no gaps/dupes. | I27: Custom (network blackhole PERF) | J27: All Kafka traffic | K27: Producer memory growth unbounded | L27: Zero event loss post-restore; backlog drain time measured; producer overflow policy proven. | M27: Broker-unreachable alarm + per-consumer lag visible. | N27: High | O27: Client behavior transfers; on-prem path is same class of fault as PROD DX loss. | P27: 3 | Q27: 5 | R27: =P27*Q27 | S27: 2 | T27: CE-KFK-06 | W27: Proposed | X27: =IF(P27=5,"Almost Certain",IF(P27=4,"Likely",IF(P27=3,"Possible",IF(P27=2,"Unlikely","Rare")))) | Y27: =IF(R27>=16,"Critical",IF(R27>=9,"High",IF(R27>=4,"Medium","Opportunistic")))
A28: CE-KFK-02 | B28: MBUS unreachable during EOD window | C28: Messaging-Kafka | D28: Compound | E28: Recon + processors | F28: DTR primarily | G28: MBUS outage timed across CBS EOD Completion publication. | H28: DTR's missing-trigger handling (see PIPE-06) engages; recon completes late-but-correct via defined recovery, inside business tolerance. | I28: Custom timing | J28: EOD processing | K28: Recon SLA breach unmanaged | L28: Recovery path exercised end-to-end; late-recon comms path (EDX/Ops) fires. | M28: EOD-event-absence alarm with deadline semantics (suspected gap). | N28: High | O28: — | P28: 2 | Q28: 5 | R28: =P28*Q28 | S28: 3 | T28: CE-KFK-01,CE-PIPE-06 | W28: Proposed | X28: =IF(P28=5,"Almost Certain",IF(P28=4,"Likely",IF(P28=3,"Possible",IF(P28=2,"Unlikely","Rare")))) | Y28: =IF(R28>=16,"Critical",IF(R28>=9,"High",IF(R28>=4,"Medium","Opportunistic")))
A29: CE-KFK-03 | B29: Consumer rebalance storm | C29: Messaging-Kafka | D29: Infrastructure | E29: Event processor | F29: DBE or DTE | G29: Repeatedly kill/restart consumer tasks to force serial rebalances. | H29: Rebalance protocol (cooperative?) limits pause; no duplicate enrichment side-effects; lag recovers between storms. | I29: FIS stop-task loop | J29: One consumer group | K29: Duplicate enriched events downstream | L29: Processing-pause per rebalance quantified; assignment strategy validated. | M29: Rebalance frequency alarmed as abnormal. | N29: High | O29: — | P29: 3 | Q29: 3 | R29: =P29*Q29 | S29: 2 | T29: CE-COM-04 | W29: Proposed | X29: =IF(P29=5,"Almost Certain",IF(P29=4,"Likely",IF(P29=3,"Possible",IF(P29=2,"Unlikely","Rare")))) | Y29: =IF(R29>=16,"Critical",IF(R29>=9,"High",IF(R29>=4,"Medium","Opportunistic")))
A30: CE-KFK-04 | B30: Poison message handling | C30: Messaging-Kafka | D30: Application | E30: Event processor | F30: DBE, DTE, DSC, DAL (each) | G30: Publish malformed/contract-violating event to PERF topic. | H30: Consumer parks/DLQs the message and CONTINUES — one bad event cannot halt the partition (classic head-of-line risk). | I30: Custom producer (PERF topics) | J30: One partition | K30: Partition stalled >5 min | L30: Skip/park behavior proven per consumer; replay procedure exists. | M30: Poison/parked-message alarm fires with payload pointer. | N30: High | O30: Logic-level. | P30: 4 | Q30: 4 | R30: =P30*Q30 | S30: 1 | W30: Proposed | X30: =IF(P30=5,"Almost Certain",IF(P30=4,"Likely",IF(P30=3,"Possible",IF(P30=2,"Unlikely","Rare")))) | Y30: =IF(R30>=16,"Critical",IF(R30>=9,"High",IF(R30>=4,"Medium","Opportunistic")))
A31: CE-KFK-05 | B31: Duplicate delivery idempotency | C31: Messaging-Kafka | D31: Application | E31: Event processor | F31: DBE, DTE, DSC, DAL (each) | G31: Re-publish already-processed events (at-least-once reality). | H31: Every consumer is effectively idempotent: no duplicate enriched events to AU/ETU, no duplicate alerts to NOTIFY, no double cache writes. | I31: Custom producer | J31: Downstream consumers | K31: Any duplicate side-effect | L31: Idempotency proven per consumer per event type. | M31: Duplicate-detection metrics exist (nice-to-have). | N31: High | O31: Logic-level. | P31: 4 | Q31: 4 | R31: =P31*Q31 | S31: 1 | W31: Proposed | X31: =IF(P31=5,"Almost Certain",IF(P31=4,"Likely",IF(P31=3,"Possible",IF(P31=2,"Unlikely","Rare")))) | Y31: =IF(R31>=16,"Critical",IF(R31>=9,"High",IF(R31>=4,"Medium","Opportunistic")))
A32: CE-KFK-06 | B32: Consumer lag accumulation & drain | C32: Messaging-Kafka | D32: Infrastructure | E32: Event processor | F32: DBE, DTE | G32: Pause consumption (scale to 0) for a bounded window, then resume. | H32: Backlog drains within recovery-time model; ordering preserved; downstream (AU/ETU) absorbs burst. | I32: Scale-to-zero + resume | J32: One consumer group | K32: Retention risk approached | L32: Drain rate measured ⇒ max tolerable outage derived (feeds KFK-01/02). | M32: Lag alarm thresholds validated against real drain math. | N32: Medium | O32: Throughput differs in PERF; drain RATE transfers, absolute times don't. | P32: 3 | Q32: 3 | R32: =P32*Q32 | S32: 1 | W32: Proposed | X32: =IF(P32=5,"Almost Certain",IF(P32=4,"Likely",IF(P32=3,"Possible",IF(P32=2,"Unlikely","Rare")))) | Y32: =IF(R32>=16,"Critical",IF(R32>=9,"High",IF(R32>=4,"Medium","Opportunistic")))
A33: CE-KFK-07 | B33: IDP OAUTHBEARER token failure (Kafka auth) | C33: Messaging-Kafka | D33: Infrastructure | E33: All Kafka clients | F33: One consumer + one producer | G33: Block IDP token issuance for Kafka SASL auth; include re-auth boundary. | H33: Existing sessions survive to re-auth boundary; failed re-auth backs off sanely (no auth-storm against IDP); clear failure signature. | I33: Custom (IDP path block PERF) | J33: Kafka connectivity | K33: Auth retry storm | L33: Session lifetime + backoff behavior documented; recovery clean. | M33: Kafka-auth failure distinct from broker-unreachable in alerts. | N33: High | O33: — | P33: 2 | Q33: 4 | R33: =P33*Q33 | S33: 2 | W33: Proposed | X33: =IF(P33=5,"Almost Certain",IF(P33=4,"Likely",IF(P33=3,"Possible",IF(P33=2,"Unlikely","Rare")))) | Y33: =IF(R33>=16,"Critical",IF(R33>=9,"High",IF(R33>=4,"Medium","Opportunistic")))
A34: CE-KFK-08 | B34: KMS key access denial — encrypted topics | C34: Messaging-Kafka | D34: Infrastructure | E34: Publisher/consumer | F34: DSM, DBE (subledger/balance event aliases) | G34: Deny kms:Decrypt/Encrypt on topic keys for the service role. | H34: Publish/consume fails closed with explicit KMS error; no silent drop; processing halts visibly and resumes on restore. | I34: Custom (KMS key policy PERF) | J34: Encrypted event flows | K34: Silent event loss | L34: Zero loss; halt-and-resume clean. | M34: KMS-denial signature alarmed. | N34: High | O34: — | P34: 2 | Q34: 4 | R34: =P34*Q34 | S34: 2 | W34: Proposed | X34: =IF(P34=5,"Almost Certain",IF(P34=4,"Likely",IF(P34=3,"Possible",IF(P34=2,"Unlikely","Rare")))) | Y34: =IF(R34>=16,"Critical",IF(R34>=9,"High",IF(R34>=4,"Medium","Opportunistic")))
A35: CE-KFK-09 | B35: PLACEHOLDER — Kafka SaaS migration scenario set | C35: Messaging-Kafka | D35: TBD | E35: Event processor | F35: TBD | G35: Reserved: re-run KFK-01..08 against Kafka SaaS on AWS; add SaaS-specific faults (quota throttling, private-link path, provider AZ events). | H35: TBD when platform selected. | I35: TBD | J35: TBD | K35: TBD | L35: TBD | M35: TBD | N35: TBD | O35: Per user direction: placeholder only, do not plan yet. | P35: 0 | Q35: 0 | R35: =P35*Q35 | S35: 4 | T35: CE-KFK-01 | W35: Proposed | X35: =IF(P35=5,"Almost Certain",IF(P35=4,"Likely",IF(P35=3,"Possible",IF(P35=2,"Unlikely","Rare")))) | Y35: =IF(R35>=16,"Critical",IF(R35>=9,"High",IF(R35>=4,"Medium","Opportunistic")))
A36: CE-PIPE-01 | B36: Input file late/missing at cutoff | C36: Pipeline-Recon | D36: Application | E36: Recon/pipeline | F36: DTR + EDX path | G36: Withhold RDF/ADF/CDF file for one bank past cutoff. | H36: EventBridge SLA validator detects absence at cutoff and EDX email notification fires (narrative step 2a); recon for other banks proceeds unaffected. | I36: Custom (withhold in PERF) | J36: One bank's recon | K36: Cross-bank impact | L36: Per-bank isolation proven; notification content actionable. | M36: SLA-validator alarm + email verified end-to-end. | N36: High | O36: Same mechanism as PROD. | P36: 4 | Q36: 4 | R36: =P36*Q36 | S36: 1 | W36: Proposed | X36: =IF(P36=5,"Almost Certain",IF(P36=4,"Likely",IF(P36=3,"Possible",IF(P36=2,"Unlikely","Rare")))) | Y36: =IF(R36>=16,"Critical",IF(R36>=9,"High",IF(R36>=4,"Medium","Opportunistic")))
A37: CE-PIPE-02 | B37: Corrupt / malformed input file | C37: Pipeline-Recon | D37: Application | E37: Recon/pipeline | F37: DTR (Lambda validate/parse) | G37: Deliver structurally invalid and semantically invalid files. | H37: Validation Lambda rejects cleanly; rejection reaches Ops/EDX; no partial ingestion poisons downstream SQS. | I37: Custom file injection | J37: One file's flow | K37: Partial ingestion detected | L37: Reject path + quarantine proven; reprocess-after-fix works. | M37: Rejection alarmed with file identity. | N37: High | O37: — | P37: 4 | Q37: 4 | R37: =P37*Q37 | S37: 1 | W37: Proposed | X37: =IF(P37=5,"Almost Certain",IF(P37=4,"Likely",IF(P37=3,"Possible",IF(P37=2,"Unlikely","Rare")))) | Y37: =IF(R37>=16,"Critical",IF(R37>=9,"High",IF(R37>=4,"Medium","Opportunistic")))
A38: CE-PIPE-03 | B38: Duplicate file delivery | C38: Pipeline-Recon | D38: Application | E38: Recon/pipeline | F38: DTR | G38: Deliver the same file twice (and same-name-different-content variant). | H38: Ingestion is idempotent by file identity; no duplicate transaction records enter reconciliation; conflict variant is flagged, not silently overwritten. | I38: Custom file injection | J38: One bank's recon | K38: Duplicate records in recon set | L38: Dedup keys proven; conflict handling explicit. | M38: Duplicate-delivery event logged/alarmed. | N38: High | O38: — | P38: 3 | Q38: 4 | R38: =P38*Q38 | S38: 1 | W38: Proposed | X38: =IF(P38=5,"Almost Certain",IF(P38=4,"Likely",IF(P38=3,"Possible",IF(P38=2,"Unlikely","Rare")))) | Y38: =IF(R38>=16,"Critical",IF(R38>=9,"High",IF(R38>=4,"Medium","Opportunistic")))
A39: CE-PIPE-04 | B39: Lambda throttling on large-file day | C39: Pipeline-Recon | D39: Infrastructure | E39: Recon/pipeline | F39: DTR chunking Lambda | G39: Lower reserved concurrency in PERF + inject peak-size file set. | H39: Throttled invocations retry via SQS without loss or duplication of chunks; end-to-end completes within window at degraded rate. | I39: Custom (concurrency limit) | J39: Chunking stage | K39: Chunk loss or duplication | L39: Exactly-once chunk effects; window math validated for peak day. | M39: Throttle + queue-age alarms fire before SLA risk. | N39: Medium | O39: PERF file volumes smaller — use synthetic peak set. | P39: 3 | Q39: 4 | R39: =P39*Q39 | S39: 2 | W39: Proposed | X39: =IF(P39=5,"Almost Certain",IF(P39=4,"Likely",IF(P39=3,"Possible",IF(P39=2,"Unlikely","Rare")))) | Y39: =IF(R39>=16,"Critical",IF(R39>=9,"High",IF(R39>=4,"Medium","Opportunistic")))
A40: CE-PIPE-05 | B40: SQS DLQ + redrive validation | C40: Pipeline-Recon | D40: Infrastructure | E40: Recon/pipeline | F40: DTR queues (+ DCM weekly-job queue) | G40: Force message processing failures to exhaust receive count. | H40: Messages land in DLQ (not lost, not infinitely retried); redrive procedure restores processing without duplication. | I40: Custom (failure injection) | J40: One queue | K40: Message loss | L40: maxReceiveCount/visibility tuned; redrive runbook proven. | M40: DLQ depth alarm fires at first message. | N40: High | O40: — | P40: 3 | Q40: 4 | R40: =P40*Q40 | S40: 1 | W40: Proposed | X40: =IF(P40=5,"Almost Certain",IF(P40=4,"Likely",IF(P40=3,"Possible",IF(P40=2,"Unlikely","Rare")))) | Y40: =IF(R40>=16,"Critical",IF(R40>=9,"High",IF(R40>=4,"Medium","Opportunistic")))
...

Sheet Priority Model
A1: Dimension | B1: Score | C1: Tier / Label | D1: Definition
A2: Likelihood | B2: 5 | C2: Almost Certain | D2: Expected routinely in normal operations (task recycles, single-node events, transient dependency errors).
A3: Likelihood | B3: 4 | C3: Likely | D3: Expected multiple times per year (consumer rebalances, duplicate event delivery, malformed inputs, gray dependency latency).
A4: Likelihood | B4: 3 | C4: Possible | D4: Plausible annually (writer failover, cache failover, AZ impairment, message-broker outage, throttling events).
A5: Likelihood | B5: 2 | C5: Unlikely | D5: Rare but credible (regional service degradation, IAM/KMS policy faults, identity-provider outage, proxy endpoint loss).
A6: Likelihood | B6: 1 | C6: Rare | D6: Exceptional (full region loss, orchestrator failure mid-failover).
A7: Severity | B7: 5 | D7: Data integrity / financial correctness at risk (duplicate writes, incorrect reconciliation, split-brain writes) OR platform-wide outage OR a missed critical processing obligation.
A8: Severity | B8: 4 | D8: Journey outage or major degradation for one or more critical journeys; unrecoverable-without-human events.
A9: Severity | B9: 3 | D9: Single-service degradation with journey-level slowdown; self-healing expected.
A10: Severity | B10: 2 | D10: Localized, transient, absorbed by redundancy; customer-invisible if systems behave.
A11: Severity | B11: 1 | D11: Negligible customer/system impact; hygiene validation.
A12: Priority | B12: L × S | D12: Computed in the catalog (column R) as Likelihood × Severity. Risk Rating (column Y): 16–25 = Critical; 9–15 = High; 4–8 = Medium; 1–3 = Opportunistic.
A13: Wave | B13: 1 | C13: Foundation | D13: Detection baseline + isolated singles with contained blast radius + integrity-critical logic tests (idempotency, dual-trigger, breaker paths, timeout chain).
A14: Wave | B14: 2 | C14: Breadth | D14: Remaining singles across all fault domains; infra faults needing custom tooling; external-dependency injection.
A15: Wave | B15: 3 | C15: Depth | D15: Compounds + coordination-heavy scenarios; on-call drills. Entry: prerequisite singles Confirmed.
A16: Wave | B16: 4 | C16: Capstone | D16: Region/DR drills, orchestrated-failover under test, pilot-light/DR-posture activation, capstone game day. Entry: Waves 1–3 evidence pack + stakeholder sign-off.
A17: Rule | B17: — | D17: A scenario's Wave may never precede any of its Prereq IDs' waves. Likelihood/Severity are proposals — recalibrate against your organization's incident history / FMEA ledger during the FMEA-Ref mapping pass, and again once the code/infra scan (see App & Infra Scan Instructions tabs) produces real evidence.
A19: Likelihood Tier Distribution (live from Scenario Catalog)
A20: Tier | B20: Count
A21: Almost Certain | B21: =COUNTIF('Scenario Catalog'!$X$2:$X$91,A21)
A22: Likely | B22: =COUNTIF('Scenario Catalog'!$X$2:$X$91,A22)
A23: Possible | B23: =COUNTIF('Scenario Catalog'!$X$2:$X$91,A23)
A24: Unlikely | B24: =COUNTIF('Scenario Catalog'!$X$2:$X$91,A24)
A25: Rare | B25: =COUNTIF('Scenario Catalog'!$X$2:$X$91,A25)
A26: Total | B26: =SUM(B21:B25)
A29: Risk Rating Distribution (live from Scenario Catalog)
A30: Rating | B30: Count
A31: Critical | B31: =COUNTIF('Scenario Catalog'!$Y$2:$Y$91,A31)
A32: High | B32: =COUNTIF('Scenario Catalog'!$Y$2:$Y$91,A32)
A33: Medium | B33: =COUNTIF('Scenario Catalog'!$Y$2:$Y$91,A33)
A34: Opportunistic | B34: =COUNTIF('Scenario Catalog'!$Y$2:$Y$91,A34)
A35: Total | B35: =SUM(B31:B34)

Sheet Wave Plan
A1: Wave | B1: Theme | C1: Entry Criteria | D1: Exit Criteria | E1: # Scenarios (live) | F1: Sum Priority (live)
A2: 1 | B2: Detection baseline + contained singles + integrity logic (idempotency, dual-trigger, breaker both paths, timeout chain, DSM state, recon restart) | C2: PERF load harness ready; FIS onboarded; Dynatrace/CloudWatch access for evidence capture; game-day runbook + abort authority named. | D2: ≥80% of Wave-1 scenarios Executed; detection scorecard (CE-OBS-01) published; findings triaged into FMEA ledger; steady-state gaps listed. | E2: =COUNTIF('Scenario Catalog'!$S$2:$S$91,A2) | F2: =SUMIF('Scenario Catalog'!$S$2:$S$91,A2,'Scenario Catalog'!$R$2:$R$91)
A3: 2 | B3: Full single-fault breadth: data/cache/kafka/pipeline/network/edge/external/config | C3: Wave-1 exit met; custom tooling built (Toxiproxy layer, IAM/KMS/ASM deny scripts, file injectors, event suppressors); FIS Fargate network actions confirmed or tc-fallback ready. | D3: All fault domains have ≥1 Confirmed scenario; per-service resilience-config truth table (breaker/retry/pool) published. | E3: =COUNTIF('Scenario Catalog'!$S$2:$S$91,A3) | F3: =SUMIF('Scenario Catalog'!$S$2:$S$91,A3,'Scenario Catalog'!$R$2:$R$91)
A4: 3 | B4: Compounds, cascades, on-call drills | C4: Prereq singles Confirmed; blast-radius model per compound approved; alarm owners engaged (CE-OBS-02 done). | D4: Compound envelope evidence (failover-under-saturation, cascade containment, IDP blast radius); MTTD/MTTI baseline from drills. | E4: =COUNTIF('Scenario Catalog'!$S$2:$S$91,A4) | F4: =SUMIF('Scenario Catalog'!$S$2:$S$91,A4,'Scenario Catalog'!$R$2:$R$91)
A5: 4 | B5: Region/DR: R53, orchestrated failover, orchestrator-under-test, pilot light, mid-recon failover, capstone game day | C5: Waves 1–3 evidence pack; leadership sign-off; dr-orchestrator PERF parity confirmed; rollback/abort rehearsed. | D5: RTO/RPO evidence per DR posture (A/A, A/P, 3-Active, Pilot Light); capstone game-day report — the program's leadership deliverable. | E5: =COUNTIF('Scenario Catalog'!$S$2:$S$91,A5) | F5: =SUMIF('Scenario Catalog'!$S$2:$S$91,A5,'Scenario Catalog'!$R$2:$R$91)
B6: TOTAL | E6: =SUM(E2:E5)

Sheet Coverage Matrix
A1: Scenario counts by Fault Domain × Wave (live from catalog)
A2: Fault Domain | B2: Wave 1 | C2: Wave 2 | D2: Wave 3 | E2: Wave 4 | F2: Total
A3: Compute | B3: =COUNTIFS('Scenario Catalog'!$C$2:$C$91,$A3,'Scenario Catalog'!$S$2:$S$91,1) | C3: =COUNTIFS('Scenario Catalog'!$C$2:$C$91,$A3,'Scenario Catalog'!$S$2:$S$91,2) | D3: =COUNTIFS('Scenario Catalog'!$C$2:$C$91,$A3,'Scenario Catalog'!$S$2:$S$91,3) | E3: =COUNTIFS('Scenario Catalog'!$C$2:$C$91,$A3,'Scenario Catalog'!$S$2:$S$91,4) | F3: =SUM(B3:E3)
A4: Resource | B4: =COUNTIFS('Scenario Catalog'!$C$2:$C$91,$A4,'Scenario Catalog'!$S$2:$S$91,1) | C4: =COUNTIFS('Scenario Catalog'!$C$2:$C$91,$A4,'Scenario Catalog'!$S$2:$S$91,2) | D4: =COUNTIFS('Scenario Catalog'!$C$2:$C$91,$A4,'Scenario Catalog'!$S$2:$S$91,3) | E4: =COUNTIFS('Scenario Catalog'!$C$2:$C$91,$A4,'Scenario Catalog'!$S$2:$S$91,4) | F4: =SUM(B4:E4)
A5: Data-Aurora | B5: =COUNTIFS('Scenario Catalog'!$C$2:$C$91,$A5,'Scenario Catalog'!$S$2:$S$91,1) | C5: =COUNTIFS('Scenario Catalog'!$C$2:$C$91,$A5,'Scenario Catalog'!$S$2:$S$91,2) | D5: =COUNTIFS('Scenario Catalog'!$C$2:$C$91,$A5,'Scenario Catalog'!$S$2:$S$91,3) | E5: =COUNTIFS('Scenario Catalog'!$C$2:$C$91,$A5,'Scenario Catalog'!$S$2:$S$91,4) | F5: =SUM(B5:E5)
A6: Cache | B6: =COUNTIFS('Scenario Catalog'!$C$2:$C$91,$A6,'Scenario Catalog'!$S$2:$S$91,1) | C6: =COUNTIFS('Scenario Catalog'!$C$2:$C$91,$A6,'Scenario Catalog'!$S$2:$S$91,2) | D6: =COUNTIFS('Scenario Catalog'!$C$2:$C$91,$A6,'Scenario Catalog'!$S$2:$S$91,3) | E6: =COUNTIFS('Scenario Catalog'!$C$2:$C$91,$A6,'Scenario Catalog'!$S$2:$S$91,4) | F6: =SUM(B6:E6)
A7: Messaging-Kafka | B7: =COUNTIFS('Scenario Catalog'!$C$2:$C$91,$A7,'Scenario Catalog'!$S$2:$S$91,1) | C7: =COUNTIFS('Scenario Catalog'!$C$2:$C$91,$A7,'Scenario Catalog'!$S$2:$S$91,2) | D7: =COUNTIFS('Scenario Catalog'!$C$2:$C$91,$A7,'Scenario Catalog'!$S$2:$S$91,3) | E7: =COUNTIFS('Scenario Catalog'!$C$2:$C$91,$A7,'Scenario Catalog'!$S$2:$S$91,4) | F7: =SUM(B7:E7)
A8: Pipeline-Recon | B8: =COUNTIFS('Scenario Catalog'!$C$2:$C$91,$A8,'Scenario Catalog'!$S$2:$S$91,1) | C8: =COUNTIFS('Scenario Catalog'!$C$2:$C$91,$A8,'Scenario Catalog'!$S$2:$S$91,2) | D8: =COUNTIFS('Scenario Catalog'!$C$2:$C$91,$A8,'Scenario Catalog'!$S$2:$S$91,3) | E8: =COUNTIFS('Scenario Catalog'!$C$2:$C$91,$A8,'Scenario Catalog'!$S$2:$S$91,4) | F8: =SUM(B8:E8)
A9: Network | B9: =COUNTIFS('Scenario Catalog'!$C$2:$C$91,$A9,'Scenario Catalog'!$S$2:$S$91,1) | C9: =COUNTIFS('Scenario Catalog'!$C$2:$C$91,$A9,'Scenario Catalog'!$S$2:$S$91,2) | D9: =COUNTIFS('Scenario Catalog'!$C$2:$C$91,$A9,'Scenario Catalog'!$S$2:$S$91,3) | E9: =COUNTIFS('Scenario Catalog'!$C$2:$C$91,$A9,'Scenario Catalog'!$S$2:$S$91,4) | F9: =SUM(B9:E9)
A10: Edge | B10: =COUNTIFS('Scenario Catalog'!$C$2:$C$91,$A10,'Scenario Catalog'!$S$2:$S$91,1) | C10: =COUNTIFS('Scenario Catalog'!$C$2:$C$91,$A10,'Scenario Catalog'!$S$2:$S$91,2) | D10: =COUNTIFS('Scenario Catalog'!$C$2:$C$91,$A10,'Scenario Catalog'!$S$2:$S$91,3) | E10: =COUNTIFS('Scenario Catalog'!$C$2:$C$91,$A10,'Scenario Catalog'!$S$2:$S$91,4) | F10: =SUM(B10:E10)
A11: External Dep | B11: =COUNTIFS('Scenario Catalog'!$C$2:$C$91,$A11,'Scenario Catalog'!$S$2:$S$91,1) | C11: =COUNTIFS('Scenario Catalog'!$C$2:$C$91,$A11,'Scenario Catalog'!$S$2:$S$91,2) | D11: =COUNTIFS('Scenario Catalog'!$C$2:$C$91,$A11,'Scenario Catalog'!$S$2:$S$91,3) | E11: =COUNTIFS('Scenario Catalog'!$C$2:$C$91,$A11,'Scenario Catalog'!$S$2:$S$91,4) | F11: =SUM(B11:E11)
A12: Config/Secrets | B12: =COUNTIFS('Scenario Catalog'!$C$2:$C$91,$A12,'Scenario Catalog'!$S$2:$S$91,1) | C12: =COUNTIFS('Scenario Catalog'!$C$2:$C$91,$A12,'Scenario Catalog'!$S$2:$S$91,2) | D12: =COUNTIFS('Scenario Catalog'!$C$2:$C$91,$A12,'Scenario Catalog'!$S$2:$S$91,3) | E12: =COUNTIFS('Scenario Catalog'!$C$2:$C$91,$A12,'Scenario Catalog'!$S$2:$S$91,4) | F12: =SUM(B12:E12)
A13: Region/DR | B13: =COUNTIFS('Scenario Catalog'!$C$2:$C$91,$A13,'Scenario Catalog'!$S$2:$S$91,1) | C13: =COUNTIFS('Scenario Catalog'!$C$2:$C$91,$A13,'Scenario Catalog'!$S$2:$S$91,2) | D13: =COUNTIFS('Scenario Catalog'!$C$2:$C$91,$A13,'Scenario Catalog'!$S$2:$S$91,3) | E13: =COUNTIFS('Scenario Catalog'!$C$2:$C$91,$A13,'Scenario Catalog'!$S$2:$S$91,4) | F13: =SUM(B13:E13)
A14: Observability | B14: =COUNTIFS('Scenario Catalog'!$C$2:$C$91,$A14,'Scenario Catalog'!$S$2:$S$91,1) | C14: =COUNTIFS('Scenario Catalog'!$C$2:$C$91,$A14,'Scenario Catalog'!$S$2:$S$91,2) | D14: =COUNTIFS('Scenario Catalog'!$C$2:$C$91,$A14,'Scenario Catalog'!$S$2:$S$91,3) | E14: =COUNTIFS('Scenario Catalog'!$C$2:$C$91,$A14,'Scenario Catalog'!$S$2:$S$91,4) | F14: =SUM(B14:E14)
... A16: Compound | B16: =COUNTIFS('Scenario Catalog'!$C$2:$C$91,$A16,'Scenario Catalog'!$S$2:$S$91,1) | C16: =COUNTIFS('Scenario Catalog'!$C$2:$C$91,$A16,'Scenario Catalog'!$S$2:$S$91,2) | D16: =COUNTIFS('Scenario Catalog'!$C$2:$C$91,$A16,'Scenario Catalog'!$S$2:$S$91,3) | E16: =COUNTIFS('Scenario Catalog'!$C$2:$C$91,$A16,'Scenario Catalog'!$S$2:$S$91,4) | F16: =SUM(B16:E16)
A17: TOTAL | B17: =SUM(B3:B16) | C17: =SUM(C3:C16) | D17: =SUM(D3:D16) | E17: =SUM(E3:E16) | F17: =SUM(F3:F16)
A19: Scenario counts by Injection Plane
A20: Injection Plane | B20: Count
A21: Infrastructure | B21: =COUNTIF('Scenario Catalog'!$D$2:$D$91,A21)
A22: Application | B22: =COUNTIF('Scenario Catalog'!$D$2:$D$91,A22)
A23: Compound | B23: =COUNTIF('Scenario Catalog'!$D$2:$D$91,A23)
A24: Detection | B24: =COUNTIF('Scenario Catalog'!$D$2:$D$91,A24)
A25: TBD | B25: =COUNTIF('Scenario Catalog'!$D$2:$D$91,A25)

Sheet Open Items
A1: # | B1: Item | C1: Why it matters / what it gates | D1: Owner | E1: Status
A2: 1 | B2: RDS Proxy split confirmation | C2: Diagram silence ≠ proof of direct connection (per your table's own caveat). CE-DB-01/02 asymmetry design assumes proxy = DCM/DBE/DTE only. Enrique checking. | D2: Enrique | E2: Open
A3: 2 | B3: FMEA Ref mapping | C3: Map all 90 scenarios to existing FMEA scenario IDs (ASSESSED items first). Recalibrate L/S scores against ledger values during the pass. | D3: Chaos team | E3: Open
A4: 3 | B4: Journey mapping | C4: Populate Journeys column against the official 16-journey list; journey criticality then feeds wave-1 sub-ordering. | D4: Chaos team | E4: Open
A5: 4 | B5: Dynatrace PERF config parity | C5: 'Team hasn't configured things properly' — CE-OBS-01 validates coverage, but first confirm the SAME monitoring config is deployed to PERF, else the scorecard measures the wrong thing. | D5: Chaos + Obs team | E5: Open
A6: 5 | B6: PERF↔PROD delta register | C6: Formal list: task counts/scaling, Aurora instance classes, data volumes, us-west-2 presence for 3-Active tier, pilot-light infra for MCC, R53/DNS config, dr-orchestrator parity, timeout config parity. Every 'Medium/Low PERF validity' flag resolves against this register. | D6: Enrique + Chaos team | E6: Open
A7: 6 | B7: FIS Fargate network actions availability | C7: Latency/loss/blackhole on Fargate needs fault-injection endpoints + pidMode:task and no blocking SCPs. If unavailable → build tc-sidecar fallback (gates CE-NET-01/02). | D7: Chaos team | E7: Open
A8: 7 | B8: External-dependency injection layer | C8: Decide and build the Toxiproxy (or equivalent) layer in front of dedicated PERF CBS + LCDP/CSU/ChannelContext paths. PERF CBS is live — inject in front, never break it. Gates all CE-EXT. | D8: Chaos team | E8: Open
A9: 8 | B9: CloudWatch alarm ownership | C9: Failover-trigger alarms owned outside app repos — CE-OBS-02 requires their owners at the table; false-trigger risk makes this a governance item, not a courtesy. | D9: Enrique | E9: Open
A10: 9 | B10: Spend-Track documentation | C10: No artifact exists. All SSE scenarios blocked until minimum documentation lands. Finding in itself. | D10: Service team | E10: Blocked
A11: 10 | B11: DLAT dependency documentation | C11: Infra-only diagram; CE-EDGE-06 doubles as the discovery exercise. | D11: Service team | E11: Open
A12: 11 | B12: Kafka SaaS placeholder | C12: CE-KFK-09 reserved. Re-plan KFK family when platform is selected. Per direction: no planning now. | D12: — | E12: Parked
A13: 12 | B13: VPC endpoint architecture | C13: Confirm PrivateLink/endpoint usage before CE-NET-04 is scoped. | D13: Enrique | E13: Open
... A15: 14 | B15: Steady-state SLI gaps | C15: Any Wave-1 scenario without a trusted steady-state signal gets logged here and becomes an observability work item before execution. | D15: Chaos team | E15: Standing

Sheet App Scan Instructions
A1: Application Code Scan — Method & Standard
A2: Durable reference for scanning ANY application repo for chaos-relevant, resilience-relevant facts. Written to be re-run unchanged on new services built after this catalog. Applies to Maven multi-module repos (root/parent pom.xml + one pom.xml per module) by default — adapt the build-file parsing step for other build tools.
A4: Non-negotiable rules (apply to every category below)
A5: • Every extracted fact carries evidence: {file path, line number, verbatim snippet}. No fact without evidence.
A6: • Never assume a framework default. If a value isn't explicitly configured, record NOT_CONFIGURED — <library>@<version> default in effect and name the version; do not state what that default is unless verified against that exact version's documentation, and mark it a human-verify item if stated.
A7: • A value only resolvable through Maven property inheritance or a profile-activated override that cannot be statically traced is AMBIGUOUS, with both candidate values and their sources recorded — never silently pick one.
A8: • Config sourced from Secrets Manager / Parameter Store / VaultSM-ASM-style vaults (i.e., the key exists in code but the value is externally resolved) is EXTERNAL_CONFIG — not resolvable from repo. Do not attempt to guess the resolved value.
A9: • A category with genuinely nothing found is NOT_FOUND, with the search patterns used listed — a clean sheet is a finding, not a skipped row.
